[2024-11-13T22:29:42.257+0000] {local_task_job_runner.py:123} INFO - ::group::Pre task execution logs
[2024-11-13T22:29:42.282+0000] {taskinstance.py:2613} INFO - Dependencies all met for dep_context=non-requeueable deps ti=<TaskInstance: rocket.notify manual__2024-11-13T22:28:09.600015+00:00 [queued]>
[2024-11-13T22:29:42.289+0000] {taskinstance.py:2613} INFO - Dependencies all met for dep_context=requeueable deps ti=<TaskInstance: rocket.notify manual__2024-11-13T22:28:09.600015+00:00 [queued]>
[2024-11-13T22:29:42.290+0000] {taskinstance.py:2866} INFO - Starting attempt 1 of 1
[2024-11-13T22:29:42.327+0000] {taskinstance.py:2889} INFO - Executing <Task(BashOperator): notify> on 2024-11-13 22:28:09.600015+00:00
[2024-11-13T22:29:42.337+0000] {warnings.py:112} WARNING - /home/***/.local/lib/python3.12/site-packages/***/task/task_runner/standard_task_runner.py:70: DeprecationWarning: This process (pid=5108) is multi-threaded, use of fork() may lead to deadlocks in the child.
  pid = os.fork()

[2024-11-13T22:29:42.338+0000] {standard_task_runner.py:104} INFO - Running: ['***', 'tasks', 'run', 'rocket', 'notify', 'manual__2024-11-13T22:28:09.600015+00:00', '--job-id', '18', '--raw', '--subdir', 'DAGS_FOLDER/rockets/rocket.py', '--cfg-path', '/tmp/tmpq8zn3v3_']
[2024-11-13T22:29:42.339+0000] {standard_task_runner.py:72} INFO - Started process 5109 to run task
[2024-11-13T22:29:42.339+0000] {standard_task_runner.py:105} INFO - Job 18: Subtask notify
[2024-11-13T22:29:42.416+0000] {task_command.py:467} INFO - Running <TaskInstance: rocket.notify manual__2024-11-13T22:28:09.600015+00:00 [running]> on host 9deca0a9ef1c
[2024-11-13T22:29:42.515+0000] {taskinstance.py:3132} INFO - Exporting env vars: AIRFLOW_CTX_DAG_OWNER='***' AIRFLOW_CTX_DAG_ID='rocket' AIRFLOW_CTX_TASK_ID='notify' AIRFLOW_CTX_EXECUTION_DATE='2024-11-13T22:28:09.600015+00:00' AIRFLOW_CTX_TRY_NUMBER='1' AIRFLOW_CTX_DAG_RUN_ID='manual__2024-11-13T22:28:09.600015+00:00'
[2024-11-13T22:29:42.519+0000] {logging_mixin.py:190} INFO - Task instance is in running state
[2024-11-13T22:29:42.520+0000] {logging_mixin.py:190} INFO -  Previous state of the Task instance: queued
[2024-11-13T22:29:42.520+0000] {logging_mixin.py:190} INFO - Current task name:notify state:running start_date:2024-11-13 22:29:42.282738+00:00
[2024-11-13T22:29:42.521+0000] {logging_mixin.py:190} INFO - Dag name:rocket and current dag run status:running
[2024-11-13T22:29:42.521+0000] {taskinstance.py:731} INFO - ::endgroup::
[2024-11-13T22:29:42.530+0000] {subprocess.py:78} INFO - Tmp dir root location: /tmp
[2024-11-13T22:29:42.532+0000] {subprocess.py:88} INFO - Running command: ['/usr/bin/bash', '-c', "echo 'There is now one image "]
[2024-11-13T22:29:42.548+0000] {subprocess.py:99} INFO - Output:
[2024-11-13T22:29:42.560+0000] {subprocess.py:106} INFO - /usr/bin/bash: -c: line 1: unexpected EOF while looking for matching `''
[2024-11-13T22:29:42.561+0000] {subprocess.py:110} INFO - Command exited with return code 2
[2024-11-13T22:29:42.575+0000] {taskinstance.py:3311} ERROR - Task failed with exception
Traceback (most recent call last):
  File "/home/airflow/.local/lib/python3.12/site-packages/airflow/models/taskinstance.py", line 767, in _execute_task
    result = _execute_callable(context=context, **execute_callable_kwargs)
             ^^^^^^^^^^^^^^^^^^^^^^^^^^^^^^^^^^^^^^^^^^^^^^^^^^^^^^^^^^^^^
  File "/home/airflow/.local/lib/python3.12/site-packages/airflow/models/taskinstance.py", line 733, in _execute_callable
    return ExecutionCallableRunner(
           ^^^^^^^^^^^^^^^^^^^^^^^^
  File "/home/airflow/.local/lib/python3.12/site-packages/airflow/utils/operator_helpers.py", line 252, in run
    return self.func(*args, **kwargs)
           ^^^^^^^^^^^^^^^^^^^^^^^^^^
  File "/home/airflow/.local/lib/python3.12/site-packages/airflow/models/baseoperator.py", line 417, in wrapper
    return func(self, *args, **kwargs)
           ^^^^^^^^^^^^^^^^^^^^^^^^^^^
  File "/home/airflow/.local/lib/python3.12/site-packages/airflow/operators/bash.py", line 276, in execute
    raise AirflowException(
airflow.exceptions.AirflowException: Bash command failed. The command returned a non-zero exit code 2.
[2024-11-13T22:29:42.582+0000] {logging_mixin.py:190} INFO - Task instance in failure state
[2024-11-13T22:29:42.583+0000] {logging_mixin.py:190} INFO - Task start:2024-11-13 22:29:42.282738+00:00 end:2024-11-13 22:29:42.582386+00:00 duration:0.299648
[2024-11-13T22:29:42.583+0000] {logging_mixin.py:190} INFO - Task:<Task(BashOperator): notify> dag:<DAG: rocket> dagrun:<DagRun rocket @ 2024-11-13 22:28:09.600015+00:00: manual__2024-11-13T22:28:09.600015+00:00, state:running, queued_at: 2024-11-13 22:28:09.690954+00:00. externally triggered: True>
[2024-11-13T22:29:42.584+0000] {logging_mixin.py:190} INFO - Failure caused by Bash command failed. The command returned a non-zero exit code 2.
[2024-11-13T22:29:42.585+0000] {taskinstance.py:1225} INFO - Marking task as FAILED. dag_id=rocket, task_id=notify, run_id=manual__2024-11-13T22:28:09.600015+00:00, execution_date=20241113T222809, start_date=20241113T222942, end_date=20241113T222942
[2024-11-13T22:29:42.600+0000] {taskinstance.py:340} INFO - ::group::Post task execution logs
[2024-11-13T22:29:42.603+0000] {standard_task_runner.py:124} ERROR - Failed to execute job 18 for task notify (Bash command failed. The command returned a non-zero exit code 2.; 5109)
Traceback (most recent call last):
  File "/home/airflow/.local/lib/python3.12/site-packages/airflow/task/task_runner/standard_task_runner.py", line 117, in _start_by_fork
    ret = args.func(args, dag=self.dag)
          ^^^^^^^^^^^^^^^^^^^^^^^^^^^^^
  File "/home/airflow/.local/lib/python3.12/site-packages/airflow/cli/cli_config.py", line 49, in command
    return func(*args, **kwargs)
           ^^^^^^^^^^^^^^^^^^^^^
  File "/home/airflow/.local/lib/python3.12/site-packages/airflow/utils/cli.py", line 116, in wrapper
    return f(*args, **kwargs)
           ^^^^^^^^^^^^^^^^^^
  File "/home/airflow/.local/lib/python3.12/site-packages/airflow/cli/commands/task_command.py", line 483, in task_run
    task_return_code = _run_task_by_selected_method(args, _dag, ti)
                       ^^^^^^^^^^^^^^^^^^^^^^^^^^^^^^^^^^^^^^^^^^^^
  File "/home/airflow/.local/lib/python3.12/site-packages/airflow/cli/commands/task_command.py", line 256, in _run_task_by_selected_method
    return _run_raw_task(args, ti)
           ^^^^^^^^^^^^^^^^^^^^^^^
  File "/home/airflow/.local/lib/python3.12/site-packages/airflow/cli/commands/task_command.py", line 341, in _run_raw_task
    return ti._run_raw_task(
           ^^^^^^^^^^^^^^^^^
  File "/home/airflow/.local/lib/python3.12/site-packages/airflow/utils/session.py", line 97, in wrapper
    return func(*args, session=session, **kwargs)
           ^^^^^^^^^^^^^^^^^^^^^^^^^^^^^^^^^^^^^^
  File "/home/airflow/.local/lib/python3.12/site-packages/airflow/models/taskinstance.py", line 3005, in _run_raw_task
    return _run_raw_task(
           ^^^^^^^^^^^^^^
  File "/home/airflow/.local/lib/python3.12/site-packages/airflow/models/taskinstance.py", line 273, in _run_raw_task
    TaskInstance._execute_task_with_callbacks(
  File "/home/airflow/.local/lib/python3.12/site-packages/airflow/models/taskinstance.py", line 3159, in _execute_task_with_callbacks
    result = self._execute_task(context, task_orig)
             ^^^^^^^^^^^^^^^^^^^^^^^^^^^^^^^^^^^^^^
  File "/home/airflow/.local/lib/python3.12/site-packages/airflow/models/taskinstance.py", line 3183, in _execute_task
    return _execute_task(self, context, task_orig)
           ^^^^^^^^^^^^^^^^^^^^^^^^^^^^^^^^^^^^^^^
  File "/home/airflow/.local/lib/python3.12/site-packages/airflow/models/taskinstance.py", line 767, in _execute_task
    result = _execute_callable(context=context, **execute_callable_kwargs)
             ^^^^^^^^^^^^^^^^^^^^^^^^^^^^^^^^^^^^^^^^^^^^^^^^^^^^^^^^^^^^^
  File "/home/airflow/.local/lib/python3.12/site-packages/airflow/models/taskinstance.py", line 733, in _execute_callable
    return ExecutionCallableRunner(
           ^^^^^^^^^^^^^^^^^^^^^^^^
  File "/home/airflow/.local/lib/python3.12/site-packages/airflow/utils/operator_helpers.py", line 252, in run
    return self.func(*args, **kwargs)
           ^^^^^^^^^^^^^^^^^^^^^^^^^^
  File "/home/airflow/.local/lib/python3.12/site-packages/airflow/models/baseoperator.py", line 417, in wrapper
    return func(self, *args, **kwargs)
           ^^^^^^^^^^^^^^^^^^^^^^^^^^^
  File "/home/airflow/.local/lib/python3.12/site-packages/airflow/operators/bash.py", line 276, in execute
    raise AirflowException(
airflow.exceptions.AirflowException: Bash command failed. The command returned a non-zero exit code 2.
[2024-11-13T22:29:42.657+0000] {local_task_job_runner.py:266} INFO - Task exited with return code 1
[2024-11-13T22:29:42.699+0000] {taskinstance.py:3895} INFO - 0 downstream tasks scheduled from follow-on schedule check
[2024-11-13T22:29:42.701+0000] {local_task_job_runner.py:245} INFO - ::endgroup::
